Workbook

Sheet 00_KPI_Dashboard
A1: DASHBOARD KPI MARKETPLACE — Escenario Conservador (gráficos dinámicos)
A2: Los gráficos leen KPI_Datos. Si modificas PyG Conservador, recalcula Excel (F9) y los gráficos se actualizan. GMV ≠ ingreso SL (ingreso = 15% comisión).
A4: KPIs clave (vinculados)
A5: GMV Y3 | B5: Ingresos Y3 | C5: Neto Y3 | D5: Margen Y3 | E5: Take rate | F5: Cobertura gastos Y3
A6: =KPI_Datos!B7 | B6: =KPI_Datos!C7 | C6: =KPI_Datos!E7 | D6: =KPI_Datos!F7 | E6: =KPI_Datos!G7 | F6: =KPI_Datos!H7
A58: Leyenda de KPIs utilizados
A59: GMV: volumen de ventas de vendedores (actividad; no es facturación propia de la SL).
A60: Ingresos: comisión 15% sobre GMV (ingreso de la SL).
A61: Take rate: Ingresos / GMV (debe ser ~15%).
A62: Cobertura de gastos: Ingresos / Gastos (>100% = ingresos cubren gastos).
A63: Margen neto: Resultado neto / Ingresos.
A64: Estacionalidad: refleja pico turístico estival (alineado a EOTR Zamora).
A65: Escenarios C/R/O: Conservador = referencia; Realista/Optimista = sensibilidad.

Sheet KPI_Datos
A1: Tablas KPI (no borrar: alimentan los gráficos del Dashboard)
A3: A. Evolución anual — Conservador (fórmulas dinámicas) | J3: F. Tarjetas KPI (Conservador)
A4: Año | B4: GMV | C4: Ingresos | D4: Gastos | E4: Neto | F4: Margen neto | G4: Take rate | H4: Cobertura gastos | J4: KPI | K4: Valor
A5: 1 | B5: =SUMIF('PyG Conservador'!$A:$A,A5,'PyG Conservador'!$C:$C) | C5: =SUMIF('PyG Conservador'!$A:$A,A5,'PyG Conservador'!$D:$D) | D5: =SUMIF('PyG Conservador'!$A:$A,A5,'PyG Conservador'!$Q:$Q) | E5: =SUMIF('PyG Conservador'!$A:$A,A5,'PyG Conservador'!$T:$T) | F5: =IF(C5=0,0,E5/C5) | G5: =IF(B5=0,0,C5/B5) | H5: =IF(D5=0,0,C5/D5) | J5: GMV Y3 | K5: =B7
A6: 2 | B6: =SUMIF('PyG Conservador'!$A:$A,A6,'PyG Conservador'!$C:$C) | C6: =SUMIF('PyG Conservador'!$A:$A,A6,'PyG Conservador'!$D:$D) | D6: =SUMIF('PyG Conservador'!$A:$A,A6,'PyG Conservador'!$Q:$Q) | E6: =SUMIF('PyG Conservador'!$A:$A,A6,'PyG Conservador'!$T:$T) | F6: =IF(C6=0,0,E6/C6) | G6: =IF(B6=0,0,C6/B6) | H6: =IF(D6=0,0,C6/D6) | J6: Ingresos Y3 | K6: =C7
A7: 3 | B7: =SUMIF('PyG Conservador'!$A:$A,A7,'PyG Conservador'!$C:$C) | C7: =SUMIF('PyG Conservador'!$A:$A,A7,'PyG Conservador'!$D:$D) | D7: =SUMIF('PyG Conservador'!$A:$A,A7,'PyG Conservador'!$Q:$Q) | E7: =SUMIF('PyG Conservador'!$A:$A,A7,'PyG Conservador'!$T:$T) | F7: =IF(C7=0,0,E7/C7) | G7: =IF(B7=0,0,C7/B7) | H7: =IF(D7=0,0,C7/D7) | J7: Neto Y3 | K7: =E7
A8: 4 | B8: =SUMIF('PyG Conservador'!$A:$A,A8,'PyG Conservador'!$C:$C) | C8: =SUMIF('PyG Conservador'!$A:$A,A8,'PyG Conservador'!$D:$D) | D8: =SUMIF('PyG Conservador'!$A:$A,A8,'PyG Conservador'!$Q:$Q) | E8: =SUMIF('PyG Conservador'!$A:$A,A8,'PyG Conservador'!$T:$T) | F8: =IF(C8=0,0,E8/C8) | G8: =IF(B8=0,0,C8/B8) | H8: =IF(D8=0,0,C8/D8) | J8: Margen neto Y3 | K8: =F7
A9: 5 | B9: =SUMIF('PyG Conservador'!$A:$A,A9,'PyG Conservador'!$C:$C) | C9: =SUMIF('PyG Conservador'!$A:$A,A9,'PyG Conservador'!$D:$D) | D9: =SUMIF('PyG Conservador'!$A:$A,A9,'PyG Conservador'!$Q:$Q) | E9: =SUMIF('PyG Conservador'!$A:$A,A9,'PyG Conservador'!$T:$T) | F9: =IF(C9=0,0,E9/C9) | G9: =IF(B9=0,0,C9/B9) | H9: =IF(D9=0,0,C9/D9) | J9: Take rate | K9: =G7
J10: Cobertura gastos Y3 | K10: =H7
J11: GMV equilibrio mes | K11: 11400
A12: B. Comparativa GMV por escenario | J12: Vendedores obj. Y3 | K12: 11
A13: Año | B13: Conservador | C13: Realista | D13: Optimista | J13: Comisión marketplace | K13: 0.15
A14: 1 | B14: 40000 | C14: 75000 | D14: 110000 | J14: Inv. + 15% dividendos | K14: 34500
A15: 2 | B15: 140000 | C15: 260000 | D15: 400000
A16: 3 | B16: 220000 | C16: 400000 | D16: 620000
A17: 4 | B17: 280000 | C17: 520000 | D17: 800000
A18: 5 | B18: 360000 | C18: 680000 | D18: 1050000
A21: C. Comparativa Resultado neto por escenario
A22: Año | B22: Conservador | C22: Realista | D22: Optimista
A23: 1 | B23: -4380 | C23: -4425 | D23: -3510
A24: 2 | B24: 459 | C24: 153 | D24: 3876
A25: 3 | B25: 7803 | C25: 7752 | D25: 13790
A26: 4 | B26: 14688 | C26: 16453 | D26: 21757
A27: 5 | B27: 23868 | C27: 32201 | D27: 39367
A30: D. Estacionalidad GMV — Año 2 Conservador (fórmulas)
A31: Mes | B31: GMV | C31: Ingresos
A32: Enero | B32: ='PyG Conservador'!C15 | C32: ='PyG Conservador'!D15
A33: Febrero | B33: ='PyG Conservador'!C16 | C33: ='PyG Conservador'!D16
A34: Marzo | B34: ='PyG Conservador'!C17 | C34: ='PyG Conservador'!D17
A35: Abril | B35: ='PyG Conservador'!C18 | C35: ='PyG Conservador'!D18
A36: Mayo | B36: ='PyG Conservador'!C19 | C36: ='PyG Conservador'!D19
A37: Junio | B37: ='PyG Conservador'!C20 | C37: ='PyG Conservador'!D20
A38: Julio | B38: ='PyG Conservador'!C21 | C38: ='PyG Conservador'!D21
A39: Agosto | B39: ='PyG Conservador'!C22 | C39: ='PyG Conservador'!D22
A40: Septiembre | B40: ='PyG Conservador'!C23 | C40: ='PyG Conservador'!D23
A41: Octubre | B41: ='PyG Conservador'!C24 | C41: ='PyG Conservador'!D24
A42: Noviembre | B42: ='PyG Conservador'!C25 | C42: ='PyG Conservador'!D25
A43: Diciembre | B43: ='PyG Conservador'!C26 | C43: ='PyG Conservador'!D26
A46: E. Estructura de gastos — Año 3 Conservador (fórmulas)
A47: Partida | B47: Importe
...

Sheet PyG Realista
A1: ESCENARIO REALISTA (hipótesis) — mayor GMV y gasto; no validado con ventas reales
A2: Año | B2: Mes | C2: GMV vendedores | D2: Ingresos comisión (15%) | E2: Coste medios pago | F2: Personal | G2: Transportes/logística | H2: Marketing | I2: Hosting/software | J2: Gestoría/contabilidad | K2: Seguros | L2: Telefonía/Internet | M2: Suministros/oficina | N2: Otros corrientes | O2: Amortizaciones | P2: Gastos financieros | Q2: Total gastos | R2: Resultado antes impuestos | S2: Impuesto Sociedades | T2: Resultado neto
A3: 1 | B3: Enero | C3: 0 | D3: 0 | E3: 0 | F3: 0 | G3: 0 | H3: 50 | I3: 120 | J3: 150 | K3: 40 | L3: 45 | M3: 55 | N3: 40 | O3: 0 | P3: 15 | Q3: =SUM(E3:P3) | R3: =D3-Q3 | S3: =MAX(0,R3*0.15) | T3: =R3-S3
A4: 1 | B4: Febrero | C4: 0 | D4: 0 | E4: 0 | F4: 0 | G4: 0 | H4: 50 | I4: 120 | J4: 150 | K4: 40 | L4: 45 | M4: 55 | N4: 40 | O4: 0 | P4: 15 | Q4: =SUM(E4:P4) | R4: =D4-Q4 | S4: =MAX(0,R4*0.15) | T4: =R4-S4
A5: 1 | B5: Marzo | C5: 0 | D5: 0 | E5: 0 | F5: 0 | G5: 0 | H5: 50 | I5: 120 | J5: 150 | K5: 40 | L5: 45 | M5: 55 | N5: 40 | O5: 0 | P5: 15 | Q5: =SUM(E5:P5) | R5: =D5-Q5 | S5: =MAX(0,R5*0.15) | T5: =R5-S5
A6: 1 | B6: Abril | C6: 0 | D6: 0 | E6: 0 | F6: 0 | G6: 0 | H6: 50 | I6: 120 | J6: 150 | K6: 40 | L6: 45 | M6: 55 | N6: 40 | O6: 0 | P6: 15 | Q6: =SUM(E6:P6) | R6: =D6-Q6 | S6: =MAX(0,R6*0.15) | T6: =R6-S6
A7: 1 | B7: Mayo | C7: 0 | D7: 0 | E7: 0 | F7: 0 | G7: 0 | H7: 50 | I7: 120 | J7: 150 | K7: 40 | L7: 45 | M7: 55 | N7: 40 | O7: 0 | P7: 15 | Q7: =SUM(E7:P7) | R7: =D7-Q7 | S7: =MAX(0,R7*0.15) | T7: =R7-S7
A8: 1 | B8: Junio | C8: 0 | D8: 0 | E8: 0 | F8: 0 | G8: 0 | H8: 50 | I8: 120 | J8: 150 | K8: 40 | L8: 45 | M8: 55 | N8: 40 | O8: 0 | P8: 15 | Q8: =SUM(E8:P8) | R8: =D8-Q8 | S8: =MAX(0,R8*0.15) | T8: =R8-S8
A9: 1 | B9: Julio | C9: 14214.95 | D9: 2132.24 | E9: 213.22 | F9: 0 | G9: 50 | H9: 700 | I9: 220 | J9: 180 | K9: 50 | L9: 55 | M9: 70 | N9: 60 | O9: 500 | P9: 25 | Q9: =SUM(E9:P9) | R9: =D9-Q9 | S9: =MAX(0,R9*0.15) | T9: =R9-S9
A10: 1 | B10: Agosto | C10: 20611.68 | D10: 3091.75 | E10: 309.18 | F10: 0 | G10: 50 | H10: 700 | I10: 220 | J10: 180 | K10: 50 | L10: 55 | M10: 70 | N10: 60 | O10: 500 | P10: 25 | Q10: =SUM(E10:P10) | R10: =D10-Q10 | S10: =MAX(0,R10*0.15) | T10: =R10-S10
A11: 1 | B11: Septiembre | C11: 10145.54 | D11: 1521.83 | E11: 152.18 | F11: 0 | G11: 50 | H11: 700 | I11: 220 | J11: 180 | K11: 50 | L11: 55 | M11: 70 | N11: 60 | O11: 500 | P11: 25 | Q11: =SUM(E11:P11) | R11: =D11-Q11 | S11: =MAX(0,R11*0.15) | T11: =R11-S11
A12: 1 | B12: Octubre | C12: 11251.53 | D12: 1687.73 | E12: 168.77 | F12: 0 | G12: 50 | H12: 700 | I12: 220 | J12: 180 | K12: 50 | L12: 55 | M12: 70 | N12: 60 | O12: 500 | P12: 25 | Q12: =SUM(E12:P12) | R12: =D12-Q12 | S12: =MAX(0,R12*0.15) | T12: =R12-S12
A13: 1 | B13: Noviembre | C13: 9721.47 | D13: 1458.22 | E13: 145.82 | F13: 0 | G13: 50 | H13: 700 | I13: 220 | J13: 180 | K13: 50 | L13: 55 | M13: 70 | N13: 60 | O13: 500 | P13: 25 | Q13: =SUM(E13:P13) | R13: =D13-Q13 | S13: =MAX(0,R13*0.15) | T13: =R13-S13
A14: 1 | B14: Diciembre | C14: 9054.82 | D14: 1358.22 | E14: 135.82 | F14: 0 | G14: 50 | H14: 700 | I14: 220 | J14: 180 | K14: 50 | L14: 55 | M14: 70 | N14: 60 | O14: 500 | P14: 25 | Q14: =SUM(E14:P14) | R14: =D14-Q14 | S14: =MAX(0,R14*0.15) | T14: =R14-S14
... A62: 5 | B62: Diciembre | C62: 50478.24 | D62: 7571.74 | E62: 757.17 | F62: 1000 | G62: 50 | H62: 1833 | I62: 670 | J62: 180 | K62: 50 | L62: 55 | M62: 70 | N62: 60 | O62: 500 | P62: 25 | Q62: =SUM(E62:P62) | R62: =D62-Q62 | S62: =MAX(0,R62*0.15) | T62: =R62-S62

Sheet PyG Optimista
A1: ESCENARIO OPTIMISTA (hipótesis) — escalado agresivo; no validado con ventas reales
A2: Año | B2: Mes | C2: GMV vendedores | D2: Ingresos comisión (15%) | E2: Coste medios pago | F2: Personal | G2: Transportes/logística | H2: Marketing | I2: Hosting/software | J2: Gestoría/contabilidad | K2: Seguros | L2: Telefonía/Internet | M2: Suministros/oficina | N2: Otros corrientes | O2: Amortizaciones | P2: Gastos financieros | Q2: Total gastos | R2: Resultado antes impuestos | S2: Impuesto Sociedades | T2: Resultado neto
A3: 1 | B3: Enero | C3: 0 | D3: 0 | E3: 0 | F3: 0 | G3: 0 | H3: 100 | I3: 150 | J3: 180 | K3: 50 | L3: 55 | M3: 70 | N3: 60 | O3: 0 | P3: 25 | Q3: =SUM(E3:P3) | R3: =D3-Q3 | S3: =MAX(0,R3*0.15) | T3: =R3-S3
A4: 1 | B4: Febrero | C4: 0 | D4: 0 | E4: 0 | F4: 0 | G4: 0 | H4: 100 | I4: 150 | J4: 180 | K4: 50 | L4: 55 | M4: 70 | N4: 60 | O4: 0 | P4: 25 | Q4: =SUM(E4:P4) | R4: =D4-Q4 | S4: =MAX(0,R4*0.15) | T4: =R4-S4
A5: 1 | B5: Marzo | C5: 0 | D5: 0 | E5: 0 | F5: 0 | G5: 0 | H5: 100 | I5: 150 | J5: 180 | K5: 50 | L5: 55 | M5: 70 | N5: 60 | O5: 0 | P5: 25 | Q5: =SUM(E5:P5) | R5: =D5-Q5 | S5: =MAX(0,R5*0.15) | T5: =R5-S5
A6: 1 | B6: Abril | C6: 0 | D6: 0 | E6: 0 | F6: 0 | G6: 0 | H6: 100 | I6: 150 | J6: 180 | K6: 50 | L6: 55 | M6: 70 | N6: 60 | O6: 0 | P6: 25 | Q6: =SUM(E6:P6) | R6: =D6-Q6 | S6: =MAX(0,R6*0.15) | T6: =R6-S6
A7: 1 | B7: Mayo | C7: 0 | D7: 0 | E7: 0 | F7: 0 | G7: 0 | H7: 100 | I7: 150 | J7: 180 | K7: 50 | L7: 55 | M7: 70 | N7: 60 | O7: 0 | P7: 25 | Q7: =SUM(E7:P7) | R7: =D7-Q7 | S7: =MAX(0,R7*0.15) | T7: =R7-S7
A8: 1 | B8: Junio | C8: 0 | D8: 0 | E8: 0 | F8: 0 | G8: 0 | H8: 100 | I8: 150 | J8: 180 | K8: 50 | L8: 55 | M8: 70 | N8: 60 | O8: 0 | P8: 25 | Q8: =SUM(E8:P8) | R8: =D8-Q8 | S8: =MAX(0,R8*0.15) | T8: =R8-S8
A9: 1 | B9: Julio | C9: 20848.6 | D9: 3127.29 | E9: 312.73 | F9: 0 | G9: 100 | H9: 1000 | I9: 250 | J9: 200 | K9: 60 | L9: 60 | M9: 80 | N9: 80 | O9: 500 | P9: 40 | Q9: =SUM(E9:P9) | R9: =D9-Q9 | S9: =MAX(0,R9*0.15) | T9: =R9-S9
A10: 1 | B10: Agosto | C10: 30230.47 | D10: 4534.57 | E10: 453.46 | F10: 0 | G10: 100 | H10: 1000 | I10: 250 | J10: 200 | K10: 60 | L10: 60 | M10: 80 | N10: 80 | O10: 500 | P10: 40 | Q10: =SUM(E10:P10) | R10: =D10-Q10 | S10: =MAX(0,R10*0.15) | T10: =R10-S10
A11: 1 | B11: Septiembre | C11: 14880.13 | D11: 2232.02 | E11: 223.2 | F11: 0 | G11: 100 | H11: 1000 | I11: 250 | J11: 200 | K11: 60 | L11: 60 | M11: 80 | N11: 80 | O11: 500 | P11: 40 | Q11: =SUM(E11:P11) | R11: =D11-Q11 | S11: =MAX(0,R11*0.15) | T11: =R11-S11
A12: 1 | B12: Octubre | C12: 16502.24 | D12: 2475.34 | E12: 247.53 | F12: 0 | G12: 100 | H12: 1000 | I12: 250 | J12: 200 | K12: 60 | L12: 60 | M12: 80 | N12: 80 | O12: 500 | P12: 40 | Q12: =SUM(E12:P12) | R12: =D12-Q12 | S12: =MAX(0,R12*0.15) | T12: =R12-S12
A13: 1 | B13: Noviembre | C13: 14258.15 | D13: 2138.72 | E13: 213.87 | F13: 0 | G13: 100 | H13: 1000 | I13: 250 | J13: 200 | K13: 60 | L13: 60 | M13: 80 | N13: 80 | O13: 500 | P13: 40 | Q13: =SUM(E13:P13) | R13: =D13-Q13 | S13: =MAX(0,R13*0.15) | T13: =R13-S13
A14: 1 | B14: Diciembre | C14: 13280.41 | D14: 1992.06 | E14: 199.21 | F14: 0 | G14: 100 | H14: 1000 | I14: 250 | J14: 200 | K14: 60 | L14: 60 | M14: 80 | N14: 80 | O14: 500 | P14: 40 | Q14: =SUM(E14:P14) | R14: =D14-Q14 | S14: =MAX(0,R14*0.15) | T14: =R14-S14
... A62: 5 | B62: Diciembre | C62: 77944.35 | D62: 11691.65 | E62: 1169.17 | F62: 2500 | G62: 100 | H62: 3333 | I62: 1000 | J62: 200 | K62: 60 | L62: 60 | M62: 80 | N62: 80 | O62: 500 | P62: 40 | Q62: =SUM(E62:P62) | R62: =D62-Q62 | S62: =MAX(0,R62*0.15) | T62: =R62-S62

Sheet PyG Conservador
A1: ESCENARIO CONSERVADOR (activo) — GMV≠ingreso SL | Y1: venta jul–dic | Amortización desde lanzamiento
A2: Año | B2: Mes | C2: GMV vendedores | D2: Ingresos comisión (15%) | E2: Coste medios pago | F2: Personal | G2: Transportes/logística | H2: Marketing | I2: Hosting/software | J2: Gestoría/contabilidad | K2: Seguros | L2: Telefonía/Internet | M2: Suministros/oficina | N2: Otros corrientes | O2: Amortizaciones | P2: Gastos financieros | Q2: Total gastos | R2: Resultado antes impuestos | S2: Impuesto Sociedades | T2: Resultado neto
A3: 1 | B3: Enero | C3: 0 | D3: 0 | E3: 0 | F3: 0 | G3: 0 | H3: 0 | I3: 80 | J3: 120 | K3: 30 | L3: 35 | M3: 40 | N3: 25 | O3: 0 | P3: 10 | Q3: =SUM(E3:P3) | R3: =D3-Q3 | S3: =MAX(0,R3*0.15) | T3: =R3-S3
A4: 1 | B4: Febrero | C4: 0 | D4: 0 | E4: 0 | F4: 0 | G4: 0 | H4: 0 | I4: 80 | J4: 120 | K4: 30 | L4: 35 | M4: 40 | N4: 25 | O4: 0 | P4: 10 | Q4: =SUM(E4:P4) | R4: =D4-Q4 | S4: =MAX(0,R4*0.15) | T4: =R4-S4
A5: 1 | B5: Marzo | C5: 0 | D5: 0 | E5: 0 | F5: 0 | G5: 0 | H5: 0 | I5: 80 | J5: 120 | K5: 30 | L5: 35 | M5: 40 | N5: 25 | O5: 0 | P5: 10 | Q5: =SUM(E5:P5) | R5: =D5-Q5 | S5: =MAX(0,R5*0.15) | T5: =R5-S5
A6: 1 | B6: Abril | C6: 0 | D6: 0 | E6: 0 | F6: 0 | G6: 0 | H6: 0 | I6: 80 | J6: 120 | K6: 30 | L6: 35 | M6: 40 | N6: 25 | O6: 0 | P6: 10 | Q6: =SUM(E6:P6) | R6: =D6-Q6 | S6: =MAX(0,R6*0.15) | T6: =R6-S6
A7: 1 | B7: Mayo | C7: 0 | D7: 0 | E7: 0 | F7: 0 | G7: 0 | H7: 0 | I7: 80 | J7: 120 | K7: 30 | L7: 35 | M7: 40 | N7: 25 | O7: 0 | P7: 10 | Q7: =SUM(E7:P7) | R7: =D7-Q7 | S7: =MAX(0,R7*0.15) | T7: =R7-S7
A8: 1 | B8: Junio | C8: 0 | D8: 0 | E8: 0 | F8: 0 | G8: 0 | H8: 0 | I8: 80 | J8: 120 | K8: 30 | L8: 35 | M8: 40 | N8: 25 | O8: 0 | P8: 10 | Q8: =SUM(E8:P8) | R8: =D8-Q8 | S8: =MAX(0,R8*0.15) | T8: =R8-S8
A9: 1 | B9: Julio | C9: 7581.31 | D9: 1137.2 | E9: 113.72 | F9: 0 | G9: 0 | H9: 350 | I9: 180 | J9: 120 | K9: 30 | L9: 35 | M9: 40 | N9: 25 | O9: 500 | P9: 10 | Q9: =SUM(E9:P9) | R9: =D9-Q9 | S9: =MAX(0,R9*0.15) | T9: =R9-S9
A10: 1 | B10: Agosto | C10: 10992.9 | D10: 1648.93 | E10: 164.89 | F10: 0 | G10: 0 | H10: 350 | I10: 180 | J10: 120 | K10: 30 | L10: 35 | M10: 40 | N10: 25 | O10: 500 | P10: 10 | Q10: =SUM(E10:P10) | R10: =D10-Q10 | S10: =MAX(0,R10*0.15) | T10: =R10-S10
A11: 1 | B11: Septiembre | C11: 5410.96 | D11: 811.64 | E11: 81.16 | F11: 0 | G11: 0 | H11: 350 | I11: 180 | J11: 120 | K11: 30 | L11: 35 | M11: 40 | N11: 25 | O11: 500 | P11: 10 | Q11: =SUM(E11:P11) | R11: =D11-Q11 | S11: =MAX(0,R11*0.15) | T11: =R11-S11
A12: 1 | B12: Octubre | C12: 6000.81 | D12: 900.12 | E12: 90.01 | F12: 0 | G12: 0 | H12: 350 | I12: 180 | J12: 120 | K12: 30 | L12: 35 | M12: 40 | N12: 25 | O12: 500 | P12: 10 | Q12: =SUM(E12:P12) | R12: =D12-Q12 | S12: =MAX(0,R12*0.15) | T12: =R12-S12
A13: 1 | B13: Noviembre | C13: 5184.78 | D13: 777.72 | E13: 77.77 | F13: 0 | G13: 0 | H13: 350 | I13: 180 | J13: 120 | K13: 30 | L13: 35 | M13: 40 | N13: 25 | O13: 500 | P13: 10 | Q13: =SUM(E13:P13) | R13: =D13-Q13 | S13: =MAX(0,R13*0.15) | T13: =R13-S13
A14: 1 | B14: Diciembre | C14: 4829.24 | D14: 724.39 | E14: 72.44 | F14: 0 | G14: 0 | H14: 350 | I14: 180 | J14: 120 | K14: 30 | L14: 35 | M14: 40 | N14: 25 | O14: 500 | P14: 10 | Q14: =SUM(E14:P14) | R14: =D14-Q14 | S14: =MAX(0,R14*0.15) | T14: =R14-S14
... A62: 5 | B62: Diciembre | C62: 26723.78 | D62: 4008.57 | E62: 400.86 | F62: 150 | G62: 0 | H62: 550 | I62: 250 | J62: 120 | K62: 30 | L62: 35 | M62: 40 | N62: 25 | O62: 500 | P62: 10 | Q62: =SUM(E62:P62) | R62: =D62-Q62 | S62: =MAX(0,R62*0.15) | T62: =R62-S62

Sheet Parámetros
A1: Parámetro | B1: Valor | C1: Comentario
A2: % comisión | B2: 0.15 | C2: Ingresos SL = GMV × 15%
A3: IVA referencia | B3: 0.21 | C3: No entra en PyG operativa
A4: IS orientativo | B4: 0.15 | C4: No es liquidación fiscal
A5: Escenario de referencia | B5: CONSERVADOR | C5: PyG Conservador = base memoria/ICECYL
A6: GMV Y1 conservador | B6: 40000 | C6: → 6,000 € comisión (6 meses venta)
A7: GMV Y2 conservador | B7: 140000 | C7: → 21,000 € comisión
A8: GMV Y3 conservador | B8: 220000 | C8: → 33,000 € comisión
A9: % medios de pago / GMV | B9: 0.015 | C9: Pasarela/Connect orientativo
A10: Amortización anual | B10: 6000 | C10: 30.000/5; en Y1 solo jul–dic
A11: Inversión referencia | B11: 30000 | C11: Activo tecnológico / umbral ICECYL
A12: Objetivo dividendos 5 años | B12: 0.15 | C12: ≥15% sobre la inversión (además de recuperarla)
A13: Neto acumulado mínimo | B13: 34500 | C13: Recuperar 30k + 4,5k dividendos
A14: Compras mercancía | B14: 0 | C14: Intermediación: sin COGS
A15: Suavizado Y1 | B15: Sí | C15: Amort. y marketing comercial desde lanzamiento; H1 costes mínimos

Sheet Drivers y equilibrio
A1: Drivers (conservador) y punto de equilibrio
A3: Año | B3: Vendedores | C3: GMV €/vend/mes | D3: Meses venta | E3: GMV anual | F3: Ingresos 15%
A4: 1 | B4: 5 | C4: 1333.33 | D4: 6 | E4: 40000 | F4: 6000
A5: 2 | B5: 8 | C5: 1458.33 | D5: 12 | E5: 140000 | F5: 21000
A6: 3 | B6: 11 | C6: 1666.67 | D6: 12 | E6: 220000 | F6: 33000
A7: 4 | B7: 13 | C7: 1794.87 | D7: 12 | E7: 280000 | F7: 42000
A8: 5 | B8: 15 | C8: 2000 | D8: 12 | E8: 360000 | F8: 54000
A10: Umbral orientativo Y3+ (con amortización; opex contenido)
A11: Gastos fijos mensuales ≈ | B11: 1710
A12: GMV mínimo mensual (÷15%) | B12: 11400
A13: Con 11 vendedores → GMV/vend/mes | B13: 1036.36
A15: Objetivo financiero (conservador)
A16: Inversión de referencia | B16: 30000
A17: Dividendos mínimos (15%) | B17: 4500
A18: Neto acumulado objetivo (5 años) | B18: 34500
A19: Neto acumulado proyectado (conservador) | B19: 42438 | C19: OK

Sheet Escenarios 3 vías
A1: Comparativa rápida (detalle mensual en PyG Conservador / Realista / Optimista)
A3: Escenario | B3: Año | C3: GMV | D3: Ingresos 15% | E3: Gastos | F3: RAI
A4: Conservador | B4: 1 | C4: 40000 | D4: 6000 | E4: 10380 | F4: -4380
A5: Conservador | B5: 2 | C5: 140000 | D5: 21000 | E5: 20460 | F5: 540
A6: Conservador | B6: 3 | C6: 220000 | D6: 33000 | E6: 23820 | F6: 9180
A7: Conservador | B7: 4 | C7: 280000 | D7: 42000 | E7: 24720 | F7: 17280
A8: Conservador | B8: 5 | C8: 360000 | D8: 54000 | E8: 25920 | F8: 28080
A9: Realista | B9: 1 | C9: 75000 | D9: 11250 | E9: 15675 | F9: -4425
A10: Realista | B10: 2 | C10: 260000 | D10: 39000 | E10: 38820 | F10: 180
A11: Realista | B11: 3 | C11: 400000 | D11: 60000 | E11: 50880 | F11: 9120
A12: Realista | B12: 4 | C12: 520000 | D12: 78000 | E12: 58644 | F12: 19356
A13: Realista | B13: 5 | C13: 680000 | D13: 102000 | E13: 64116 | F13: 37884
A14: Optimista | B14: 1 | C14: 110000 | D14: 16500 | E14: 20010 | F14: -3510
A15: Optimista | B15: 2 | C15: 400000 | D15: 60000 | E15: 55440 | F15: 4560
... A18: Optimista | B18: 5 | C18: 1050000 | D18: 157500 | E18: 111186 | F18: 46314

Sheet Resumen anual
A1: Resumen anual — tres escenarios (ingresos = GMV × 15%)
A3: 🔴 Conservador (referencia)
A4: Año | B4: GMV | C4: Ingresos 15% | D4: Total gastos | E4: RAI | F4: IS | G4: Neto | H4: Margen neto
A5: 1 | B5: 40000 | C5: 6000 | D5: 10379.99 | E5: -4379.99 | F5: 0 | G5: -4379.99 | H5: -0.72999833
A6: 2 | B6: 139999.99 | C6: 21000.01 | D6: 20460.01 | E6: 540 | F6: 81 | G6: 459 | H6: 0.021857132
A7: 3 | B7: 220000.01 | C7: 33000 | D7: 23820.01 | E7: 9179.99 | F7: 1377 | G7: 7802.99 | H7: 0.23645429
A8: 4 | B8: 280000 | C8: 41999.99 | D8: 24720.01 | E8: 17279.98 | F8: 2592 | G8: 14687.98 | H8: 0.34971396
A9: 5 | B9: 360000 | C9: 54000.01 | D9: 25920 | E9: 28080.01 | F9: 4212 | G9: 23868.01 | H9: 0.44200008
A12: 🟡 Realista (hipótesis)
A13: Año | B13: GMV | C13: Ingresos 15% | D13: Total gastos | E13: RAI | F13: IS | G13: Neto | H13: Margen neto
A14: 1 | B14: 74999.99 | C14: 11249.99 | D14: 15674.99 | E14: -4425 | F14: 0 | G14: -4425 | H14: -0.39333368
A15: 2 | B15: 260000.01 | C15: 38999.99 | D15: 38820.01 | E15: 179.98 | F15: 27 | G15: 152.98 | H15: 0.003922642
A16: 3 | B16: 399999.99 | C16: 59999.99 | D16: 50880.01 | E16: 9119.98 | F16: 1368 | G16: 7751.98 | H16: 0.12919974
A17: 4 | B17: 519999.99 | C17: 78000.01 | D17: 58643.98 | E17: 19356.03 | F17: 2903.4 | G17: 16452.63 | H17: 0.21093107
A18: 5 | B18: 680000 | C18: 102000.01 | D18: 64115.99 | E18: 37884.02 | F18: 5682.6 | G18: 32201.42 | H18: 0.31570014
A21: 🟢 Optimista (hipótesis)
A22: Año | B22: GMV | C22: Ingresos 15% | D22: Total gastos | E22: RAI | F22: IS | G22: Neto | H22: Margen neto
A23: 1 | B23: 110000 | C23: 16500 | D23: 20010 | E23: -3510 | F23: 0 | G23: -3510 | H23: -0.21272727
A24: 2 | B24: 399999.99 | C24: 59999.99 | D24: 55440.01 | E24: 4559.98 | F24: 684 | G24: 3875.98 | H24: 0.064599727
A25: 3 | B25: 619999.98 | C25: 92999.99 | D25: 76776 | E25: 16223.99 | F25: 2433.6 | G25: 13790.39 | H25: 0.1482838
A26: 4 | B26: 800000 | C26: 120000.02 | D26: 94403.99 | E26: 25596.03 | F26: 3839.4 | G26: 21756.63 | H26: 0.18130518
A27: 5 | B27: 1050000 | C27: 157500.01 | D27: 111185.98 | E27: 46314.03 | F27: 6947.1 | G27: 39366.93 | H27: 0.24994872
A30: Y1 suavizado en conservador: amortización solo desde julio (capitalización en lanzamiento); marketing comercial en H2; H1 = estructura mínima. Detalle mes a mes en hojas PyG Conservador / Realista / Optimista.

Sheet Partidas contables
A1: Grupo | B1: Partida | C1: Tratamiento en PyG | D1: Observaciones
A2: 6 | B2: Personal / Seguridad Social | C2: Gasto | D2: Nóminas, seguros sociales y otros costes de personal
A3: 62 | B3: Servicios exteriores | C3: Gasto | D3: Hosting, software, gestoría, seguros, marketing, suministros, etc.
A4: 62 | B4: Transportes / logística | C4: Gasto | D4: Solo si los soporta la sociedad; si los paga el vendedor, no duplicar
A5: 62 | B5: Servicios profesionales | C5: Gasto | D5: Asesoría jurídica, fiscal, consultoría, desarrollo externalizado, etc.
A6: 62 | B6: Publicidad y marketing | C6: Gasto | D6: Campañas, contenidos y promoción
A7: 62 | B7: Reparaciones y mantenimiento | C7: Gasto | D7: Mantenimiento de equipos/plataforma
A8: 62 | B8: Tributos | C8: Gasto | D8: Tasas y tributos que no sean impuesto sobre beneficios
A9: 63 | B9: Impuestos | C9: Gasto | D9: Impuestos no recuperables y otros tributos según corresponda
A10: 66 | B10: Gastos financieros | C10: Gasto | D10: Intereses y costes financieros
A11: 68 | B11: Amortización del inmovilizado | C11: Gasto | D11: Activos materiales e inmateriales amortizables
A12: 70/75 | B12: Ingresos por comisiones | C12: Ingreso | D12: 15% sobre facturación/GMV de vendedores, según contrato y modelo real
... A16: — | B16: Compras de mercaderías | C16: No aplica (modelo inicial) | D16: Marketplace intermediación: stock y venta son del vendedor.

Sheet Notas y control
A1: Tema | B1: Criterio
A2: GMV | B2: No es ingreso de la SL.
A3: Ingresos | B3: 15% comisión sobre GMV.
A4: Y1 suavizado | B4: Amortización y marketing comercial desde julio; H1 costes mínimos de estructura.
A5: 3 PyG | B5: Conservador = referencia. Realista/Optimista = sensibilidad mensual completa.
A6: Compras | B6: 0 € — sin reventa de stock.
A7: IS/IVA | B7: IS orientativo; IVA fuera de PyG.
A8: Subvenciones | B8: No incluidas como ingreso de explotación.
A9: Dashboard | B9: Abrir hoja 00_KPI_Dashboard: gráficos dinámicos desde KPI_Datos / PyG.
